Workbook

Sheet Cover
A1: BLACK BOX LTD - INVESTMENT SUMMARY
A2: NSE: BBOX | BSE: 500463 | Sector: Digital Infrastructure / Enterprise Networking & Systems Integration
B4: RECOMMENDATION & TARGET
B5: Recommendation | C5: =Summary!B19
B6: Current Price (INR, ~12-Aug-2026) | C6: 830
B7: Target Price (INR, blended) | C7: =Summary!B16
B8: Upside / (Downside) | C8: =C7/C6-1
B9: Valuation date | C9: =TODAY()
B10: Prepared by | C10: Om Prakash Panda
B12: VALUATION SUMMARY (INR/share)
B13: DCF (intrinsic; WACC ~13.9%, g 5%, mid-year) | C13: =DCF!C41
B14: Relative (26x FY27E EPS, base) | C14: =Relative!F20
B15: EV/EBITDA cross-check (15x FY27E) | C15: =Summary!B14
B16: Blended target | C16: =Summary!B16
B17: Street coverage: thin (2-3 analysts); MF ownership ~0%
B19: INVESTMENT THESIS
B20: The market treats Black Box as a de-risked Indian proxy for the global AI / data-centre infrastructure build-out and prices it at ~50-70x trailing earnings on the promise of a US$2bn-by-FY30 revenue plan. My research suggests the business, though genuinely turned around (EBITDA margin ~4%->9%, net worth negative->Rs1,287cr), remains a thin-margin (~9%), cash-light, no-pricing-power systems integrator with high customer/geographic concentration, a heavy Essar/Ruia promoter overhang and a growth plan already running behind its own timeline (FY26 revenue guidance cut; US$2bn target slipped FY29->FY30). At the current price there is little margin of safety.
B22: THREE CORE INVESTMENT PILLARS
B23: Pillar 1 - Genuine operational turnaround, but now fully priced
B24: From a distressed, negative-net-worth 2019 merger, BB lifted EBITDA margin from ~4% (FY23) to ~9% (FY26), repaired the balance sheet and built a US$949mn backlog with 20-year Fortune-500 relationships (Bank of America the largest). The improvement is real and largely structural - but the equity already capitalises it at a premium to global peers.
B25: Pillar 2 - AI/data-centre exposure is real but indirect, thin-margin and input-constrained
B26: BB sells deployment labour, fibre and cabling into hyperscaler builds (DC mix 17%->~30%), not compute/GPUs, and wins on technical merit, not price. FY26 showed backlog can be delayed by fibre/GPU/power shortages outside BB's control. It is a participant in the capex wave, not a driver, and a tiny slice of each customer's budget.
B27: Pillar 3 - Earnings quality and cash conversion are the swing factors the market underweights
B28: Reported PAT is flattered by a ~8-10% NOL-driven tax rate (normalising to ~18-20% in the model) and by excluding 7+ quarters of 'exceptionals'; revenue was ~flat at ~Rs6,000cr for four years and free cash flow is weak/volatile (CFO negative in FY25) as growth consumes ~0.2-0.3x working capital. The US$2bn plan leans on ~Rs6,000cr of unproven serial M&A.
B30: KEY CATALYSTS (+) | E30: KEY RISKS (-)
B31: - Sustained order booking >US$300-350mn/quarter | E31: - Premium multiple (~50-70x) => de-rating risk; little margin of safety
B32: - Repeatable hyperscaler DC wins with annuity tails | E32: - Guidance-delivery risk (FY26 cut; FY30 target slipped a year)
B33: - EBITDA margin crossing 10%; exceptionals ending | E33: - Weak/volatile FCF; receivables spike (DSO ~67 in FY26)
B34: - Cross-sell into 20-yr Fortune-500 base; managed-services attach | E34: - Customer concentration (top 10 ~51%; Bank of America largest)
B35: - First clean FCF-positive year; institutional/MF entry | E35: - Promoter/governance overhang (Essar/Ruia); tax normalisation
B36: - Accretive, disciplined M&A (2S-style) | E36: - FX (94% non-INR revenue); supply-chain (fibre/GPU/power)
B38: DETAILED INVESTMENT VIEW
B39: Black Box has earned respect for execution: a small Indian company (AGC Networks) acquired the distressed, larger US-listed Black Box Corporation for ~US$17mn of equity in 2019 and turned it into a ~Rs6,300cr, ~9% EBITDA-margin global integrator with an enviable, sticky Fortune-500 client base. The FY26 backlog (US$792mn->US$949mn by Q1FY27) and the DC pivot give a credible growth narrative. But three facts temper enthusiasm: revenue was essentially flat FY22-FY26; free cash flow has been thin and often negative; and reported profit is flattered by a temporary tax rate and recurring 'exceptionals'.
B40: The valuation is built bottom-up across three methods. The DCF is the disciplined anchor: with Rf 6.8%, ERP 7.0% and a small-cap/specific-risk beta of ~1.30, cost of equity is ~15.9% and WACC ~15.1% (materially above the auto-template's 12.7% because BB is a smaller, riskier, promoter-controlled, cyclical name); at 6% terminal growth the FY27E-FY32E free cash flows discount to an intrinsic value well below the current price - i.e., today's price already embeds success.
B41: Relative valuation is where the mispricing is clearest. BB's true economic peers - WESCO (~22x P/E), Insight (~15x), Kyndryl (~5.5x EV/EBITDA), Redington (~16x), HCLTech (~19x), Allied Digital (~13x) - trade at a fraction of BB's ~65-70x. Even a generous 25x base target on FY27E EPS (a premium to peers for growth/DC exposure) sits far below the current multiple, implying limited-to-negative upside. The EV/EBITDA cross-check (15x FY27E EBITDA) corroborates.
B42: Triangulating DCF (40%), Relative (40%) and EV/EBITDA (20%) yields the blended target on the Summary sheet. The core thesis on why the market is mispricing the stock: it is extrapolating a thematic AI/DC narrative onto a thin-margin, cash-light integrator whose organic growth is unproven over a cycle, whose earnings quality is flattered, and whose promoter carries a heavy governance legacy - none of which supports a multiple that prices flawless execution as a certainty.
B43: Return profile: base case tracks the blended target (see Summary); bull case requires sustained ~20% organic growth, margins >10.5% and clean FCF (justifying a higher multiple); bear case (AI-capex digestion, dilutive raise, governance event, tax normalisation) implies a >50% de-rating. The skew from today's price is unfavourable - downside to a DCF floor well below price against limited upside unless the aggressive plan is delivered.
B45: INSTITUTIONAL CONCLUSION
B46: We initiate with a cautious stance: NEUTRAL-to-underweight on the equity (constructive on the business, cautious on the stock). Black Box is a much-improved, blue-chip-anchored integrator riding a genuine capex super-cycle, but at ~50-70x earnings, with thin margins, weak cash conversion, high concentration and a promoter overhang, the risk/reward at the current price is unattractive. We would turn constructive on a meaningful de-rating or on 2+ quarters of proven organic growth and positive free cash flow. See Summary sheet for the model-derived blended target and recommendation.

Sheet Historicals
A1: BLACK BOX LTD - HISTORICAL FINANCIALS (CONSOLIDATED)
A3: INCOME STATEMENT (in Crs) | B3: FY 17 | C3: FY 18 | D3: FY 19 | E3: FY 20 | F3: FY 21 | G3: FY 22 | H3: FY 23 | I3: FY 24 | J3: FY 25 | K3: FY 26
A4: Revenue From Operations [Gross] | D4: 1853 | E4: 4994 | F4: 4674 | G4: 5370 | H4: 6288 | I4: 6282 | J4: 5967 | K4: 6322
A5: Less: Excise/Sevice Tax/Other Levies | D5: 0 | E5: 0 | F5: 0 | G5: 0 | H5: 0 | I5: 0 | J5: 0 | K5: 0
A6: Revenue From Operations [Net] | D6: 1853 | E6: 4994 | F6: 4674 | G6: 5370 | H6: 6288 | I6: 6282 | J6: 5967 | K6: 6322
A7: Other Operating Revenues | D7: 297.41 | E7: 349.71 | F7: 0 | G7: 0 | H7: 0 | I7: 0 | J7: 0 | K7: 0
A8: Total Operating Revenues | D8: 1853 | E8: 4994 | F8: 4674 | G8: 5370 | H8: 6288 | I8: 6282 | J8: 5967 | K8: 6322
A9: Other Income | D9: 7.54 | E9: 32.1 | F9: 11 | G9: 6 | H9: 22 | I9: 19 | J9: 5 | K9: 6
A10: Total Revenue | D10: 1853 | E10: 4994 | F10: 4685 | G10: 5376 | H10: 6310 | I10: 6301 | J10: 5972 | K10: 6328
A11: EXPENSES
A12: Cost of Revenue (hardware, materials & subcontracting) | D12: 13672.8 | E12: 11854.8 | F12: 3177 | G12: 3821 | H12: 4648 | I12: 4568 | J12: 4173 | K12: 4392
A13: Purchase Of Stock-In Trade | D13: 244.84 | E13: 259.2 | F13: 0 | G13: 0 | H13: 0 | I13: 0 | J13: 0 | K13: 0
A14: Changes In Inventories Of FG,WIP And Stock-In Trade | D14: -75.37 | E14: 21.93 | F14: 0 | G14: 0 | H14: 0 | I14: 0 | J14: 0 | K14: 0
A15: Employee & Other Operating Expenses (SG&A) | D15: 922.63 | E15: 938.41 | F15: 1145 | G15: 1289 | H15: 1370 | I15: 1286 | J15: 1263 | K15: 1360
A16: Finance Costs | D16: 80.56 | E16: 102.19 | F16: 98 | G16: 74 | H16: 111 | I16: 141 | J16: 145 | K16: 158
A17: Depreciation And Amortisation Expenses | D17: 399.27 | E17: 489.03 | F17: 96 | G17: 99 | H17: 107 | I17: 114 | J17: 113 | K17: 116
A18: (folded into SG&A above) | D18: 2011.77 | E18: 2003.14 | F18: 0 | G18: 0 | H18: 0 | I18: 0 | J18: 0 | K18: 0
A19: Total Expenses | D19: 17256.5 | E19: 15668.7 | F19: 4516 | G19: 5283 | H19: 6236 | I19: 6109 | J19: 5694 | K19: 6026
A20: Profit/Loss Before Exceptional, ExtraOrdinary Items And Tax | D20: 960.96 | E20: 786.74 | F20: 169 | G20: 93 | H20: 74 | I20: 192 | J20: 278 | K20: 302
A21: Exceptional Items & Share of Assoc. (net) | D21: 0 | E21: -32.33 | F21: -73 | G21: -7 | H21: -45 | I21: -36 | J21: -66 | K21: -63
A22: Profit/Loss Before Tax | D22: 960.96 | E22: 754.41 | F22: 96 | G22: 86 | H22: 29 | I22: 156 | J22: 212 | K22: 239
A23: Tax Expenses-Continued Operations
A24: Current Tax | D24: 276.76 | E24: 233.9 | F24: 18 | G24: 13 | H24: 6 | I24: 19 | J24: 7 | K24: 22
A25: Deferred Tax | D25: 14.06 | E25: -71.74 | F25: 0 | G25: 0 | H25: 0 | I25: 0 | J25: 0 | K25: 0
A26: Total Tax Expenses | D26: 290.82 | E26: 162.16 | F26: 18 | G26: 13 | H26: 6 | I26: 19 | J26: 7 | K26: 22
A27: Profit/Loss After Tax And Before ExtraOrdinary Items | D27: 670.14 | E27: 592.25 | F27: 78 | G27: 73 | H27: 23 | I27: 137 | J27: 205 | K27: 217
A28: Profit/Loss From Continuing Operations | D28: 670.14 | E28: 592.25 | F28: 78 | G28: 73 | H28: 23 | I28: 137 | J28: 205 | K28: 217
A29: Profit/Loss From discontinuing Operations | D29: 0 | E29: 0 | F29: 0 | G29: 0 | H29: 0 | I29: 0 | J29: 0 | K29: 0
A30: Profit/Loss For The Period | D30: -79 | E30: -80 | F30: 78 | G30: 73 | H30: 24 | I30: 138 | J30: 205 | K30: 218
A31: OTHER ADDITIONAL INFORMATION
A32: EARNINGS PER SHARE
A33: Basic EPS (Rs.) | D33: 14.11 | E33: 12.47 | F33: 5.21 | G33: 4.45 | H33: 1.42 | I33: 8.2 | J33: 12.16 | K33: 12.78
A34: Diluted EPS (Rs.) | D34: 14.11 | E34: 12.47 | F34: 5.21 | G34: 4.45 | H34: 1.42 | I34: 8.2 | J34: 12.16 | K34: 12.78
A35: DIVIDEND AND DIVIDEND PERCENTAGE
A36: Equity Share Dividend | D36: 166.28 | E36: 166.28 | F36: 0 | G36: 0 | H36: 0 | I36: 0 | J36: 0 | K36: 0
A39: BALANCE SHEET (in Crs) | D39: FY 19 | E39: FY 20 | F39: FY 21 | G39: FY 22 | H39: FY 23 | I39: FY 24 | J39: FY 25 | K39: FY 26
A40: EQUITIES AND LIABILITIES
A41: SHAREHOLDER'S FUNDS
A42: Equity Share Capital | D42: 47.51 | E42: 47.51 | F42: 33 | G42: 33 | H42: 34 | I42: 34 | J42: 34 | K42: 36
A43: Total Share Capital | D43: 47.51 | E43: 47.51 | F43: 33 | G43: 33 | H43: 34 | I43: 34 | J43: 34 | K43: 36
...

Sheet Operating Drivers
A1: BLACK BOX LTD - OPERATING DRIVERS & KPIs (CONSOLIDATED)
A3: SECTION 1 — REVENUE & GROWTH (organic vs inorganic) | G3: FY 21 | H3: FY 22 | I3: FY 23 | J3: FY 24 | K3: FY 25 | L3: FY 26 | M3: FY 27E | N3: FY 28E | O3: FY 29E | P3: FY 30E | Q3: FY 31E | R3: FY 32E
A4: Total revenue | B4: INR Cr | G4: =Historicals!F6 | H4: =Historicals!G6 | I4: =Historicals!H6 | J4: =Historicals!I6 | K4: =Historicals!J6 | L4: =Historicals!K6 | M4: =Forecast!D30 | N4: =Forecast!E30 | O4: =Forecast!F30 | P4: =Forecast!G30 | Q4: =Forecast!H30 | R4: =Forecast!I30
A5: Revenue growth % YoY | B5: % | H5: =H4/G4-1 | I5: =I4/H4-1 | J5: =J4/I4-1 | K5: =K4/J4-1 | L5: =L4/K4-1 | M5: =M4/L4-1 | N5: =N4/M4-1 | O5: =O4/N4-1 | ... R5: =R4/Q4-1
A6: Inorganic (acquired) revenue added | B6: INR Cr | G6: 0 | H6: 0 | I6: 0 | J6: 0 | K6: 0 | L6: 0 | M6: =Forecast!D5 | N6: =Forecast!E5 | O6: =Forecast!F5 | P6: =Forecast!G5 | Q6: =Forecast!H5 | R6: =Forecast!I5
A7: Organic revenue growth % (ex-M&A) | B7: % | H7: =H4/G4-1 | I7: =I4/H4-1 | J7: =J4/I4-1 | K7: =K4/J4-1 | L7: =L4/K4-1 | M7: =Forecast!D4 | N7: =Forecast!E4 | O7: =Forecast!F4 | P7: =Forecast!G4 | Q7: =Forecast!H4 | R7: =Forecast!I4
A9: SECTION 2 — SEGMENT, RECURRING & GEOGRAPHIC MIX (disclosed)
A10: Global Solutions Integration (GSI) % rev | B10: % | L10: 0.84
A11: Technology Product Solutions (TPS) % rev | B11: % | L11: 0.14
A12: Other services % rev | B12: % | L12: 0.02
A13: Recurring/managed services % rev | B13: % | K13: 0.3 | L13: 0.3
A14: Data-centre revenue % (mix) | B14: % | L14: 0.17 | M14: 0.3
A15: Geo mix: North America / Europe / India | B15: % | L15: NA 69% | EU 9% | IN 6%
A16: Geo mix: APAC / LatAm / MEA | B16: % | L16: APAC 8% | LatAm 6% | MEA 2%
A18: SECTION 3 — MARGIN STRUCTURE
A19: Gross margin % | B19: % | G19: =(Historicals!F6-Historicals!F12)/Historicals!F6 | H19: =(Historicals!G6-Historicals!G12)/Historicals!G6 | I19: =(Historicals!H6-Historicals!H12)/Historicals!H6 | J19: =(Historicals!I6-Historicals!I12)/Historicals!I6 | K19: =(Historicals!J6-Historicals!J12)/Historicals!J6 | L19: =(Historicals!K6-Historicals!K12)/Historicals!K6 | M19: =1-Forecast!D6 | N19: =1-Forecast!E6 | O19: =1-Forecast!F6 | P19: =1-Forecast!G6 | Q19: =1-Forecast!H6 | R19: =1-Forecast!I6
A20: SG&A (total other opex) % rev | B20: % | G20: =Historicals!F15/Historicals!F6 | H20: =Historicals!G15/Historicals!G6 | I20: =Historicals!H15/Historicals!H6 | J20: =Historicals!I15/Historicals!I6 | K20: =Historicals!J15/Historicals!J6 | L20: =Historicals!K15/Historicals!K6 | M20: =Forecast!D9 | N20: =Forecast!E9 | O20: =Forecast!F9 | P20: =Forecast!G9 | Q20: =Forecast!H9 | R20: =Forecast!I9
A21: EBITDA margin % | B21: % | G21: =(Historicals!F6-Historicals!F12-Historicals!F15)/Historicals!F6 | H21: =(Historicals!G6-Historicals!G12-Historicals!G15)/Historicals!G6 | I21: =(Historicals!H6-Historicals!H12-Historicals!H15)/Historicals!H6 | J21: =(Historicals!I6-Historicals!I12-Historicals!I15)/Historicals!I6 | K21: =(Historicals!J6-Historicals!J12-Historicals!J15)/Historicals!J6 | L21: =(Historicals!K6-Historicals!K12-Historicals!K15)/Historicals!K6 | M21: =Forecast!D52 | N21: =Forecast!E52 | O21: =Forecast!F52 | P21: =Forecast!G52 | Q21: =Forecast!H52 | R21: =Forecast!I52
A22: EBIT margin % | B22: % | G22: =(Historicals!F22+Historicals!F16-Historicals!F21)/Historicals!F6 | H22: =(Historicals!G22+Historicals!G16-Historicals!G21)/Historicals!G6 | I22: =(Historicals!H22+Historicals!H16-Historicals!H21)/Historicals!H6 | J22: =(Historicals!I22+Historicals!I16-Historicals!I21)/Historicals!I6 | K22: =(Historicals!J22+Historicals!J16-Historicals!J21)/Historicals!J6 | L22: =(Historicals!K22+Historicals!K16-Historicals!K21)/Historicals!K6
A24: SECTION 4 — WORKING CAPITAL EFFICIENCY
A25: DSO (receivable days) | B25: days | G25: =Historicals!F76/Historicals!F6*365 | H25: =Historicals!G76/Historicals!G6*365 | I25: =Historicals!H76/Historicals!H6*365 | J25: =Historicals!I76/Historicals!I6*365 | K25: =Historicals!J76/Historicals!J6*365 | L25: =Historicals!K76/Historicals!K6*365 | M25: =Forecast!D18 | N25: =Forecast!E18 | O25: =Forecast!F18 | P25: =Forecast!G18 | Q25: =Forecast!H18 | R25: =Forecast!I18
A26: Inventory days | B26: days | G26: =Historicals!F75/Historicals!F6*365 | H26: =Historicals!G75/Historicals!G6*365 | I26: =Historicals!H75/Historicals!H6*365 | J26: =Historicals!I75/Historicals!I6*365 | K26: =Historicals!J75/Historicals!J6*365 | L26: =Historicals!K75/Historicals!K6*365 | M26: =Forecast!D19 | N26: =Forecast!E19 | O26: =Forecast!F19 | P26: =Forecast!G19 | Q26: =Forecast!H19 | R26: =Forecast!I19
A27: DPO (payable days, on revenue) | B27: days | G27: =Historicals!F56/Historicals!F6*365 | H27: =Historicals!G56/Historicals!G6*365 | I27: =Historicals!H56/Historicals!H6*365 | J27: =Historicals!I56/Historicals!I6*365 | K27: =Historicals!J56/Historicals!J6*365 | L27: =Historicals!K56/Historicals!K6*365 | M27: =Forecast!D20 | N27: =Forecast!E20 | O27: =Forecast!F20 | P27: =Forecast!G20 | Q27: =Forecast!H20 | R27: =Forecast!I20
A28: Contract assets % of revenue | B28: % | G28: =Historicals!F79/Historicals!F6 | H28: =Historicals!G79/Historicals!G6 | I28: =Historicals!H79/Historicals!H6 | J28: =Historicals!I79/Historicals!I6 | K28: =Historicals!J79/Historicals!J6 | L28: =Historicals!K79/Historicals!K6
A29: Contract liab + other CL % of revenue | B29: % | G29: =Historicals!F57/Historicals!F6 | H29: =Historicals!G57/Historicals!G6 | I29: =Historicals!H57/Historicals!H6 | J29: =Historicals!I57/Historicals!I6 | K29: =Historicals!J57/Historicals!J6 | L29: =Historicals!K57/Historicals!K6
A31: SECTION 5 — CAPITAL, RETURNS & TAX
A32: Net debt / (net cash) | B32: INR Cr | G32: =Historicals!F49+Historicals!F55-Historicals!F77 | H32: =Historicals!G49+Historicals!G55-Historicals!G77 | I32: =Historicals!H49+Historicals!H55-Historicals!H77 | J32: =Historicals!I49+Historicals!I55-Historicals!I77 | K32: =Historicals!J49+Historicals!J55-Historicals!J77 | L32: =Historicals!K49+Historicals!K55-Historicals!K77
A33: Effective tax rate | B33: % | G33: =Historicals!F26/Historicals!F22 | H33: =Historicals!G26/Historicals!G22 | I33: =Historicals!H26/Historicals!H22 | J33: =Historicals!I26/Historicals!I22 | K33: =Historicals!J26/Historicals!J22 | L33: =Historicals!K26/Historicals!K22 | M33: =Forecast!D14 | N33: =Forecast!E14 | O33: =Forecast!F14 | P33: =Forecast!G14 | Q33: =Forecast!H14 | R33: =Forecast!I14
A34: ROE (PAT / avg equity) | B34: % | H34: =Historicals!G30/AVERAGE(Historicals!F46,Historicals!G46) | I34: =Historicals!H30/AVERAGE(Historicals!G46,Historicals!H46) | J34: =Historicals!I30/AVERAGE(Historicals!H46,Historicals!I46) | K34: =Historicals!J30/AVERAGE(Historicals!I46,Historicals!J46) | L34: =Historicals!K30/AVERAGE(Historicals!J46,Historicals!K46)
A35: Capex % of revenue | B35: % | M35: =Forecast!D13 | N35: =Forecast!E13 | O35: =Forecast!F13 | P35: =Forecast!G13 | Q35: =Forecast!H13 | R35: =Forecast!I13
A36: SECTION 6 — ORDER BOOK ($mn): FY24 backlog 470 | FY25 504 | FY26 792 | FY26 bookings 1,003; avg tenure ~12-18 months
A38: SECTION 7 — CONTRACT ACCOUNTING (Ind-AS 115) - INR cr
A39: Contract Assets (unbilled revenue) | G39: 0 | H39: 44 | I39: 114 | J39: 246 | K39: 219 | L39: 280 | M39: scaled w/ revenue in Forecast (other CA)
A40: Contract Liabilities (deferred revenue/advances) | G40: 0 | H40: 523 | I40: 560 | J40: 555 | K40: 500 | L40: 576 | M40: scaled w/ revenue in Forecast (other CL)

Sheet Forecast
A1: BLACK BOX LTD - 3 STATEMENT FORECAST (CONSOLIDATED)
A3: A. KEY FORECAST ASSUMPTIONS (FY27E-FY32E) | C3: FY 26 A | D3: FY 27 E | E3: FY 28 E | F3: FY 29 E | G3: FY 30 E | H3: FY 31 E | I3: FY 32 E
A4: Organic revenue growth % | B4: % | D4: 0.13 | E4: 0.13 | F4: 0.12 | G4: 0.11 | H4: 0.1 | I4: 0.09
A5: Inorganic (acquired) revenue added (INR cr) | B5: % | D5: 500 | E5: 400 | F5: 400 | G5: 300 | H5: 300 | I5: 200
A6: Cost of revenue % of revenue | B6: % | D6: 0.695 | E6: 0.694 | F6: 0.693 | G6: 0.692 | H6: 0.692 | I6: 0.691
A7: Purchases % of revenue (n/a - folded) | B7: % | D7: 0 | E7: 0 | F7: 0 | G7: 0 | H7: 0 | I7: 0
A8: Changes in inventories % (n/a) | B8: % | D8: 0 | E8: 0 | F8: 0 | G8: 0 | H8: 0 | I8: 0
A9: Total operating expenses (SG&A) % of revenue | B9: % | D9: 0.212 | E9: 0.21 | F9: 0.208 | G9: 0.207 | H9: 0.205 | I9: 0.205
A10: Other expenses % (n/a - folded) | B10: % | D10: 0 | E10: 0 | F10: 0 | G10: 0 | H10: 0 | I10: 0
A11: Effective finance cost on borrowings (incl. lease interest & normalised FX) | B11: % | D11: 0.155 | E11: =D11 | F11: =E11 | G11: =F11 | H11: =G11 | I11: =H11
A12: Depreciation % of prior fixed assets | B12: % | D12: 0.125 | E12: 0.125 | F12: 0.125 | G12: 0.125 | H12: 0.125 | I12: 0.125
A13: Capex incl. ROU/lease & intangible additions (pure cash capex ~0.7-1.0%) | B13: % | C13: =C108/C33 | D13: 0.013 | E13: 0.012 | F13: 0.012 | G13: 0.011 | H13: 0.011 | I13: 0.011
A14: Effective tax rate (NOL depletion -> statutory ~25%) | B14: % | D14: 0.12 | E14: 0.15 | F14: 0.18 | G14: 0.21 | H14: 0.24 | I14: 0.25
A15: Dividend payout (% PAT) | B15: % | D15: 0.05 | E15: 0.05 | F15: 0.05 | G15: 0.05 | H15: 0.05 | I15: 0.05
A16: Non-current financial assets growth % | B16: % | D16: 0.08 | E16: 0.08 | F16: 0.08 | G16: 0.08 | H16: 0.08 | I16: 0.08
A17: Borrowings growth % | B17: % | D17: 0.08 | E17: 0.07 | F17: 0.06 | G17: 0.05 | H17: 0.05 | I17: 0.05
A18: Receivable days (DSO) | B18: days | D18: 62 | E18: 60 | F18: 58 | G18: 57 | H18: 56 | I18: 55
A19: Inventory days | B19: days | D19: 19 | E19: 19 | F19: 19 | G19: 19 | H19: 19 | I19: 19
A20: Payable days (DPO, on revenue) | B20: days | D20: 46 | E20: 46 | F20: 46 | G20: 46 | H20: 46 | I20: 46
A21: Minority interest growth % | B21: % | D21: 0 | E21: 0 | F21: 0 | G21: 0 | H21: 0 | I21: 0
A23: B. OPERATING DRIVERS
A24: Organic revenue (prior total x (1+organic growth)) | B24: units | C24: =Historicals!K6 | D24: =C30*(1+D4) | E24: =D30*(1+E4) | F24: =E30*(1+F4) | G24: =F30*(1+G4) | H24: =G30*(1+H4) | I24: =H30*(1+I4)
A25: Organic growth % | B25: % | D25: =D4 | E25: =E4 | F25: =F4 | G25: =G4 | H25: =H4 | I25: =I4
A26: Inorganic (acquired) revenue added | B26: INR | C26: 0 | D26: =D5 | E26: =E5 | F26: =F5 | G26: =G5 | H26: =H5 | I26: =I5
A27: Total revenue growth % | B27: % | D27: =D30/C30-1 | E27: =E30/D30-1 | F27: =F30/E30-1 | G27: =G30/F30-1 | H27: =H30/G30-1 | I27: =I30/H30-1
A29: C. INCOME STATEMENT
A30: Total Operating Revenues | B30: INR Cr | C30: =Historicals!K6 | D30: =D24+D26 | E30: =E24+E26 | F30: =F24+F26 | G30: =G24+G26 | H30: =H24+H26 | I30: =I24+I26
A31: Revenue growth % | B31: % | C31: =LN(Historicals!K6/Historicals!J6) | D31: =LN(D30/C30) | E31: =LN(E30/D30) | F31: =LN(F30/E30) | G31: =LN(G30/F30) | H31: =LN(H30/G30) | I31: =LN(I30/H30)
A32: Other Income | B32: INR Cr | C32: =Historicals!K9 | D32: =C32*1.05 | E32: =D32*1.05 | F32: =E32*1.05 | G32: =F32*1.05 | H32: =G32*1.05 | I32: =H32*1.05
A33: Total Revenue | B33: INR Cr | C33: =C30+C32 | D33: =D30+D32 | E33: =E30+E32 | F33: =F30+F32 | G33: =G30+G32 | H33: =H30+H32 | I33: =I30+I32
A34: Cost of Revenue (hardware, materials & subcontracting) | B34: INR Cr | C34: =Historicals!K12 | D34: =D30*D6 | E34: =E30*E6 | F34: =F30*F6 | G34: =G30*G6 | H34: =H30*H6 | I34: =I30*I6
A35: Purchase Of Stock-In-Trade | B35: INR Cr | C35: =Historicals!K13 | D35: =D33*D7 | E35: =E33*E7 | F35: =F33*F7 | G35: =G33*G7 | H35: =H33*H7 | I35: =I33*I7
A36: Changes In Inventories (FG/WIP/SIT) | B36: INR Cr | C36: =Historicals!K14 | D36: =D33*D8 | E36: =E33*E8 | F36: =F33*F8 | G36: =G33*G8 | H36: =H33*H8 | I36: =I33*I8
A37: Employee & Other Operating Expenses (SG&A) | B37: INR Cr | C37: =Historicals!K15 | D37: =D30*D9 | E37: =E30*E9 | F37: =F30*F9 | G37: =G30*G9 | H37: =H30*H9 | I37: =I30*I9
A38: Finance Costs | B38: INR Cr | C38: =Historicals!K16 | D38: =D11*(C59+D59+C64+D64)/2 | E38: =E11*(D59+E59+D64+E64)/2 | F38: =F11*(E59+F59+E64+F64)/2 | G38: =G11*(F59+G59+F64+G64)/2 | H38: =H11*(G59+H59+G64+H64)/2 | I38: =I11*(H59+I59+H64+I64)/2
A39: Depreciation & Amortisation | B39: INR Cr | C39: =Historicals!K17 | D39: =D12*C74 | E39: =E12*D74 | F39: =F12*E74 | G39: =G12*F74 | H39: =H12*G74 | I39: =I12*H74
A40: Other Expenses | B40: INR Cr | C40: =Historicals!K18 | D40: =D33*D10 | E40: =E33*E10 | F40: =F33*F10 | G40: =G33*G10 | H40: =H33*H10 | I40: =I33*I10
A41: Total Expenses | B41: INR Cr | C41: =SUM(C34:C40) | D41: =SUM(D34:D40) | E41: =SUM(E34:E40) | F41: =SUM(F34:F40) | G41: =SUM(G34:G40) | H41: =SUM(H34:H40) | I41: =SUM(I34:I40)
A42: PBT before exceptional | B42: INR Cr | C42: =C33-C41 | D42: =D33-D41 | E42: =E33-E41 | F42: =F33-F41 | G42: =G33-G41 | H42: =H33-H41 | I42: =I33-I41
A43: Exceptional Items (restructuring/severance - tapering) | B43: INR Cr | C43: =Historicals!K21 | D43: 90 | E43: 50 | F43: 20 | G43: 0 | H43: 0 | I43: 0
...

Sheet DCF
A1: BLACK BOX LTD - DCF
A3: WACC BUILD-UP
A4: Risk-free rate (India 10Y G-sec, ~Jun-2026) | B4: 0.068
A5: Equity risk premium (India) | B5: 0.07
A6: Beta (small-cap integrator; moderated from 1.30 toward sector norms) | B6: 1.1
A7: Cost of equity = Rf + Beta x ERP | B7: =B4+B6*B5
A8: Pre-tax cost of debt (marginal borrowing rate) | B8: 0.09
A9: Tax rate | B9: =AVERAGE(Forecast!D14:I14)
A10: After-tax cost of debt | B10: =B8*(1-B9)
A11: Equity weight | B11: 0.92
A12: Debt weight | B12: =1-B11
A13: WACC | B13: =(B11*B7)+(B12*B10)
A15: TERMINAL VALUE
A16: Terminal growth rate (g) - long-run INR nominal (USD-centric, mature) | B16: 0.05
A17: Net (debt) / cash [FY26A: borrowings 827 + ST 30 lease-adj - cash 540 ~ (287)] | B17: -287
A18: Shares outstanding (cr) | B18: 18
A19: Current market price (INR) [links Cover] | B19: =Cover!C6
A21: FCFF BUILD | B21: FY 27 E | C21: FY 28 E | D21: FY 29 E | E21: FY 30 E | F21: FY 31 E | G21: FY 32 E
A22: Revenue (from forecast) | B22: =Forecast!D33 | C22: =Forecast!E33 | D22: =Forecast!F33 | E22: =Forecast!G33 | F22: =Forecast!H33 | G22: =Forecast!I33
A23: EBIT (= PBT + finance cost) | B23: =Forecast!D44+Forecast!D38 | C23: =Forecast!E44+Forecast!E38 | D23: =Forecast!F44+Forecast!F38 | E23: =Forecast!G44+Forecast!G38 | F23: =Forecast!H44+Forecast!H38 | G23: =Forecast!I44+Forecast!I38
A24: Less: non-operating adjustment (n/a for Black Box) | B24: 0 | C24: 0 | D24: 0 | E24: 0 | F24: 0 | G24: 0
A25: Operating EBIT (for FCFF) | B25: =B23+B24 | C25: =C23+C24 | D25: =D23+D24 | E25: =E23+E24 | F25: =F23+F24 | G25: =G23+G24
A26: Less: tax on Operating EBIT | B26: =-B25*$B$9 | C26: =-C25*$B$9 | D26: =-D25*$B$9 | E26: =-E25*$B$9 | F26: =-F25*$B$9 | G26: =-G25*$B$9
A27: NOPAT | B27: =B25+B26 | C27: =C25+C26 | D27: =D25+D26 | E27: =E25+E26 | F27: =F25+F26 | G27: =G25+G26
A28: Add: depreciation & amortisation | B28: =Forecast!D39 | C28: =Forecast!E39 | D28: =Forecast!F39 | E28: =Forecast!G39 | F28: =Forecast!H39 | G28: =Forecast!I39
A29: Less: capex | B29: =-Forecast!D108 | C29: =-Forecast!E108 | D29: =-Forecast!F108 | E29: =-Forecast!G108 | F29: =-Forecast!H108 | G29: =-Forecast!I108
A30: Less: change in operating working capital | B30: =Forecast!D92 | C30: =Forecast!E92 | D30: =Forecast!F92 | E30: =Forecast!G92 | F30: =Forecast!H92 | G30: =Forecast!I92
A31: FCFF | B31: =B27+B28+B29+B30 | C31: =C27+C28+C29+C30 | D31: =D27+D28+D29+D30 | E31: =E27+E28+E29+E30 | F31: =F27+F28+F29+F30 | G31: =G27+G28+G29+G30
A32: Discount factor @ WACC (mid-year convention) | B32: =1/(1+$B$13)^0.5 | C32: =1/(1+$B$13)^1.5 | D32: =1/(1+$B$13)^2.5 | E32: =1/(1+$B$13)^3.5 | F32: =1/(1+$B$13)^4.5 | G32: =1/(1+$B$13)^5.5
A33: PV of FCFF | B33: =B31*B32 | C33: =C31*C32 | D33: =D31*D32 | E33: =E31*E32 | F33: =F31*F32 | G33: =G31*G32
A35: Sum of PV of explicit FCFF (FY27E-FY32E) | C35: =SUM(B33:G33)
A36: Terminal value @ FY32 = FCFF32 x (1+g)/(WACC-g) | C36: =G31*(1+B16)/(B13-B16)
A37: PV of terminal value (mid-year) | C37: =C36/(1+B13)^5.5
A38: Enterprise value | C38: =SUM(C37+C35)
A39: Add: net cash / (less net debt) | C39: =B17
A40: Equity value | C40: =C38+C39
A41: Target price per share (INR) | C41: =C40/B18
A42: Current price (INR) | C42: =B19
A43: Upside / (downside) vs current | C43: =C41/C42-1
A44: Memo: PV(TV) as % of EV | C44: =C37/C38
...

Sheet Relative
A1: BLACK BOX LTD - RELATIVE VALUATION (economic peers: infra integrators/distributors)
A3: Company | B3: Price (local) | C3: Mkt Cap | D3: Net debt/(cash) | E3: EV | F3: Revenue | G3: EBITDA | H3: PAT | I3: EPS | J3: ROE | K3: ROCE | L3: P/E | M3: EV/EBITDA
A4: Black Box (subject) | B4: =Cover!C6 | C4: =B4*DCF!B18 | D4: 287 | E4: =C4+D4 | F4: =Historicals!K6 | G4: =Forecast!C51 | H4: =Historicals!K30 | I4: =Historicals!K33 | J4: =Historicals!K30/AVERAGE(Historicals!J46,Historicals!K46) | K4: =(Historicals!K22+Historicals!K16)/(Historicals!K46+Historicals!K49+Historicals!K55) | L4: =C4/H4 | M4: =E4/G4
A5: WESCO International (US distr. + DC deploy) | L5: 22 | M5: 13
A6: Kyndryl (US managed infra svcs; turnaround) | L6: 30 | M6: 5.5
A7: Redington (India IT distribution/infra) | L7: 16 | M7: 9
A8: Tata Communications (India digital infra) | L8: 38 | M8: 9
A9: Mastek (India IT services - mid cap) | L9: 16 | M9: 8
A10: Happiest Minds (India digital/IT) | L10: 38 | M10: 19
A11: Peer median (economic peers) | L11: =MEDIAN(L5:L10) | M11: =MEDIAN(M5:M10)
A12: Peer mean | L12: =AVERAGE(L5:L10) | M12: =AVERAGE(M5:M10)
A13: TARGET PRICE — MULTIPLE APPLICATION
A14: Black Box FY27E EPS (consol PAT / shares) | B14: =Forecast!D49
A15: Black Box FY28E EPS | B15: =Forecast!E49
A16: Black Box FY27E EBITDA (INR cr) | B16: =Forecast!D51
A18: Case | B18: Target P/E | C18: Implied TP (P/E x FY27E EPS) | D18: Target EV/EBITDA | E18: Implied TP (EV/EBITDA) | F18: Relative TP (P/E-based)
A19: Bear (low) | B19: 20 | C19: =B19*$B$14 | D19: 11 | E19: =(D19*$B$16+DCF!$B$17)/DCF!$B$18 | F19: =C19
A20: Base | B20: 26 | C20: =B20*$B$14 | D20: 13 | E20: =(D20*$B$16+DCF!$B$17)/DCF!$B$18 | F20: =C20
A21: Bull (high) | B21: 32 | C21: =B21*$B$14 | D21: 16 | E21: =(D21*$B$16+DCF!$B$17)/DCF!$B$18 | F21: =C21
A23: Note: Peer set spans BB's closest economic analogs (WESCO, Kyndryl, Redington - low-margin integration/distribution/managed svcs) and Indian listed tech/infra (Tata Comm, Mastek, Happiest Minds). Peer median P/E ~26x, EV/EBITDA ~9x. Black Box at ~46x FY27E / ~65x trailing remains a clear premium; target multiples set at ~peer median (base 26x), a large discount to BBOX's current multiple. Multiples approximate (~Aug-2026) - refresh with live data.

Sheet Summary
A1: BLACK BOX LTD - VALUATION SUMMARY
A3: VALUATION METHOD 3 — EV/EBITDA CROSS-CHECK
A4: FY27E EBITDA (INR cr) | B4: =Forecast!D51
A5: Target EV/EBITDA (x) | B5: 12
A6: Implied Enterprise Value | B6: =B4*B5
A7: Add: net cash / (less net debt) | B7: =DCF!B17
A8: Implied Equity Value | B8: =B6+B7
A9: Shares outstanding (cr) | B9: =DCF!B18
A10: EV/EBITDA-based TP (INR/share) | B10: =B8/B9
A14: EV/EBITDA cross-check TP (INR/share) | B14: =B10
A16: BLENDED TARGET PRICE (weighted base) | B16: =SUMPRODUCT(C24:C26,E24:E26)
A17: Current price (INR) | B17: =DCF!B19
A18: Upside / (downside) vs current | B18: =B16/B17-1
A19: Recommendation | B19: =IF(B18>0.15,"BUY",IF(B18>0,"ACCUMULATE",IF(B18>-0.1,"NEUTRAL/HOLD","REDUCE")))
A22: VALUATION SUMMARY — METHOD TRIANGULATION, BLENDED TARGET & RECOMMENDATION
A23: Method | B23: Bear | C23: Base | D23: Bull | E23: Weight
A24: DCF (FCFF; WACC 13-16%, g 4-6.5%) | B24: =DCF!B57 | C24: =DCF!C41 | D24: =DCF!F51 | E24: 0.4
A25: Relative (P/E on FY27E EPS) | B25: =Relative!F19 | C25: =Relative!F20 | D25: =Relative!F21 | E25: 0.4
A26: EV/EBITDA cross-check | C26: =B10 | E26: 0.2

Sheet Assumptions
A1: BLACK BOX LTD - DETAILED ASSUMPTIONS & RESEARCH SUPPORT
A2: A. REVENUE & GROWTH DRIVERS
A3: Assumption | B3: Model value | C3: Historical trend | D3: Research & industry evidence | E3: Management commentary | F3: Govt policy / competitive benchmark | G3: Why reasonable & valuation impact | H3: Conf. | I3: Source - Date
A4: Organic revenue growth % | B4: FY27E +13% tapering to +9% by FY32E | C4: Revenue ~flat at ~Rs6,000cr FY22-26 (FY24 6,282 -> FY26 6,322); FY26 +6% | D4: AI/DC capex supercycle (global DC capex ~$430bn 2024 -> ~$1.1tn 2029); enterprise refresh | E4: Mgmt targets US$1.3bn organic (~17% CAGR) within US$2bn-by-FY30 plan | F4: WESCO/Anixter, Kyndryl in same layer | G4: Set BELOW mgmt implied ~17% - reflects unproven organic track record & backlog-conversion risk; top value driver | H4: Medium | I4: BB Q1FY27 pres; industry (NetworkWorld/IDC) - 2026
A5: Inorganic (acquired) revenue | B5: Rs500cr FY27 (2S Brazil) then Rs200-400cr/yr; ~Rs2,100cr cumulative | C5: First sizeable M&A = 2S (Brazil), ~Rs500cr, ~5-5.5x EBITDA | D5: Fragmented integrator market enables bolt-ons | E5: Mgmt aspires ~Rs6,000cr (US$700mn) inorganic by FY30 | F5: Serial acquirers (WESCO) as model | G5: Modelled WELL BELOW ~Rs6,000cr aspiration - serial M&A unproven at scale; execution/integration risk | H5: Low-Medium | I5: BB Q3FY26 call; Q1FY27 pres - 2026
A6: Segment mix (GSI / TPS / Other) | B6: GSI ~84% / TPS ~14% / Other ~2% (held ~stable) | C6: FY26 disclosed 84/14/2 | D6: GSI = services (DC, connectivity, networking, workplace, cyber); TPS = KVM/AV products | E6: Mgmt: GSI is the growth engine | F6: n/a | G6: Mix stable; TPS higher-margin, GSI faster-growing (offset) | H6: Medium | I6: BB FY26 pres p.26-27
A7: Data-centre revenue mix % | B7: 17% (FY26) -> ~30% (FY27E) | C7: DC ~17% of FY26 | D7: Hyperscaler capex $600-900bn 2026; each GW needs fibre/cabling/deploy | E7: Mgmt guides DC ~30% of FY27 | F7: WESCO DC momentum | G7: Rising DC mix is LOWER gross margin than products/managed svcs - a margin headwind, not tailwind | H7: Medium | I7: BB Q1FY27 pres
A8: Managed services / recurring % | B8: ~30%+ of revenue (rising) | C8: >30% by FY25/FY26 | D8: Day-2 annuity attach on projects ~10-15% | E8: Mgmt: converting projects to annuities (airports, healthcare, hyperscaler) | F8: n/a | G8: Higher recurring mix improves visibility & multiple quality - key positive to monitor | H8: Medium | I8: BB FY25 AR; calls
A9: Geographic mix | B9: NA ~69%, EU ~9%, APAC ~8%, India ~6%, LatAm ~6%, MEA ~2% | C9: NA-centric since 2019 Black Box Corp deal | D9: US AI/DC build-out concentrated; India margin-dilutive | E9: Mgmt scaling Europe/India/LatAm (2S) | F9: n/a | G9: 94% non-INR => FX exposure; NA drives profit; India deliberately cautious on margin | H9: Medium | I9: BB Q1FY27 pres
A10: B. MARGINS, COSTS & TAX
A11: Assumption | B11: Model value | C11: Historical trend | D11: Research & industry evidence | E11: Management commentary | F11: Govt policy / competitive benchmark | G11: Why reasonable & valuation impact | H11: Conf. | I11: Source - Date
A12: Cost of revenue % (gross margin) | B12: ~69.5% cost (gross margin ~30.5% -> 30.9%) | C12: Gross margin 26% (FY23) -> 30.5% (FY26) | D12: Mix + offshoring (~20%) support GM; rising DC mix pressures it | E12: Mgmt guides gross margin ~30.5% | F12: Integrators run ~20-35% GM | G12: Held ~flat-to-slightly-up; conservative given DC-mix drag; each 100bps GM ~Rs60cr+ EBITDA | H12: Medium-High | I12: BB pres p.22
A13: Operating expenses (SG&A) % rev | B13: 21.2% (FY27E) -> 20.5% (FY32E) | C13: Total other expenses ~21.5% (FY26) | D13: Operating leverage on higher throughput + offshoring | E13: Mgmt: fixed-cost absorption drives 10% EBITDA | F13: n/a | G13: Modest opex leverage; the main margin lever (BB has no pricing power) | H13: Medium | I13: BB calls; model
A14: EBITDA margin % | B14: 9.3% (FY27E) -> ~10.4% (FY32E) | C14: 4.3% (FY23) -> 9.0% (FY26) | D14: Operating leverage + offshoring; DC mix a drag | E14: Mgmt targets 10% by end-FY27 | F14: WESCO ~7%, Kyndryl low | G14: Reaches ~10.4% - broadly in line with mgmt 10% target, capped (thin-margin, no pricing power) | H14: Medium | I14: BB Q1FY27 pres
A15: Depreciation & capex | B15: Dep ~13% of prior fixed assets; capex ~1.5-1.8% of revenue | C15: Dep Rs116cr (FY26); asset-light, capex small | D15: Ind-AS 116 ROU depreciation is large part of D&A | E15: Mgmt: asset-light model | F15: n/a | G15: Low fixed-asset intensity; capex incl. lease/intangible additions | H15: Medium-High | I15: BB pres p.22-23
A16: Effective tax rate | B16: Normalises 12% (FY27E) -> 25% (FY32E, statutory) | C16: Reported ~3-10% (NOL-shielded) | D16: US + India NOLs deplete; converges to blended statutory ~25% | E16: Not explicitly guided | F16: India 25%, US ~21-25% | G16: AUDIT-DRIVEN: normalised toward statutory (best practice for terminal); conservative vs low reported rate | H16: Medium | I16: Filings; independent judgement
A17: Finance cost / cost of funds | B17: ~12% blended on borrowings (incl leases) | C17: Finance cost Rs158cr (FY26) incl lease interest + FX | D17: FY26 cost inflated by FX; assumes normalisation | E17: n/a | F17: n/a | G17: Bumped to 12% to capture lease + borrowing cost (ex one-off FX) | H17: Medium | I17: BB pres; model
A18: EPS trajectory / shares | B18: Shares 18.0cr (eq. cap Rs36cr / Rs2); EPS grows w/ PAT & tax normalisation | C18: FY26 EPS Rs12.78 (~17.1cr wtd avg) | D18: Year-end diluted ~18.0cr post warrant conversion | E18: Preferential warrants converted (Rs417) | F18: n/a | G18: Uses ~18.0cr diluted; PAT growth partly offset by tax normalisation | H18: Medium-High | I18: BB pres p.22-23
A19: C. WORKING CAPITAL, CAPEX & BALANCE SHEET
A20: Assumption | B20: Model value | C20: Historical trend | D20: Research & industry evidence | E20: Management commentary | F20: Govt policy / competitive benchmark | G20: Why reasonable & valuation impact | H20: Conf. | I20: Source - Date
A21: DSO (receivable days) | B21: 62 (FY27E) easing to 55 (FY32E) | C21: DSO jumped to ~67 (FY26) from ~35 (FY25) | D21: Month-end-skewed billing; OEM-supply-linked invoicing | E21: Mgmt claims normalised DSO ~55-60 | F21: n/a | G21: Kept ELEVATED & only gradually normalising - FY26 spike is a red flag; high DSO consumes cash | H21: Medium | I21: BB Q2/Q3FY26 calls
A22: Inventory (19d), DPO (46d), contract assets/liab | B22: Inventory ~19d; DPO ~46d; contract A/L scale with revenue | C22: FY26: inv ~19d, payables ~46d (on revenue); contract assets Rs280cr, liab Rs576cr | D22: Wind River licence pre-buy lifted inventory | E22: Mgmt: efficient WC | F22: n/a | G22: Growth consumes ~0.2-0.3x revenue in WC - the structural cash constraint | H22: Medium | I22: BB pres p.23; calls
A23: Capex (incl. ROU/lease & intangible additions) | B23: ~1.1-1.3% of revenue | C23: Pure cash capex ~0.7-1.0% (FY25 Rs44cr=0.7%); + ROU/intangible additions | D23: Ind-AS 116 leases: depreciation incl ROU amortisation, so investment line incl lease/intangible additions | E23: Mgmt: asset-light | F23: n/a | G23: AUDIT-DRIVEN: reduced & reclassified; pure cash capex low, balance is ROU/intangibles to keep FA roll-forward consistent | H23: Medium | I23: FY25 cash flow; independent judgement
A24: Net debt / borrowings | B24: Net debt ~Rs287cr (borrowings 827 - cash 540); borrowings grow ~5-8%/yr | C24: FY26 borrowings Rs827cr + leases Rs326cr; cash Rs540cr | D24: M&A partly debt-funded; leverage target <1.5-2x | E24: Mgmt: prudent leverage | F24: n/a | G24: Modest net debt; conservatively excludes current financial assets (Rs543cr) from cash | H24: Medium-High | I24: BB pres p.23; independent judgement
A25: D. DCF / WACC & TERMINAL VALUE
A26: Assumption | B26: Model value | C26: Historical trend | D26: Research & industry evidence | E26: Management commentary | F26: Govt policy / competitive benchmark | G26: Why reasonable & valuation impact | H26: Conf. | I26: Source - Date
A27: Risk-free rate | B27: 6.8% | C27: India 10Y G-sec ~6.8-6.9% (2026) | D27: On-the-run 10Y; INR DCF | E27: RBI easing bias | F27: Sovereign benchmark | G27: Current, market-based | H27: High | I27: ET bond market - 2026
A28: Equity risk premium | B28: 7.0% | C28: India ERP ~6-7.5% | D28: Mid-range India ERP | E28: n/a | F28: Standard India | G28: 7.0% (vs auto template 6.5%) reflects BB higher risk | H28: Medium | I28: Damodaran 2025/26
A29: Beta | B29: 1.10 (moderated from 1.30) | C29: Small-cap, cyclical, promoter overhang | D29: Sector integrator betas ~0.9-1.2 | E29: n/a | F29: Auto ~0.95 | G29: AUDIT-DRIVEN: moderated toward sector norms; Ke = 6.8% + 1.10x7.0% = 14.5% | H29: Medium | I29: Independent judgement
A30: WACC | B30: ~13.9% (was 15.2%) | C30: Ke 14.5%; after-tax Kd ~7.3%; weights 92/8 | D30: Moved toward institutional norms (audit 11-13%) | E30: n/a | F30: India small/mid-cap DCFs 12-14% | G30: AUDIT-DRIVEN: moderated; still a modest risk premium for size/governance | H30: High | I30: DCF sheet
A31: Terminal growth | B31: 5.0% (was 6%) | C31: ~4% USD nominal + INR depreciation | D31: Below India nominal GDP; USD-centric mature integrator | E31: n/a | F31: Mature-franchise terminal | G31: AUDIT-DRIVEN: lowered to conservative 5%; mid-year convention added | H31: Medium | I31: Independent judgement
A32: DCF value / share | B32: See DCF!C41 | C32: FCFF FY27E-FY32E + TV | D32: Conservative anchor; well below current price | E32: n/a | F32: Reflects 15.1% WACC / 6% g | G32: The disciplined floor (40% blend weight) | H32: Medium | I32: DCF sheet
A33: E. RELATIVE VALUATION
A34: Assumption | B34: Model value | C34: Historical trend | D34: Research & industry evidence | E34: Management commentary | F34: Govt policy / competitive benchmark | G34: Why reasonable & valuation impact | H34: Conf. | I34: Source - Date
A35: Peer set | B35: WESCO, Kyndryl, Redington, Tata Comm, Mastek, Happiest Minds | C35: Peer median P/E ~26x, EV/EBITDA ~9x; BB ~46-65x | D35: AUDIT-DRIVEN: spans global economic analogs + Indian listed tech/infra | E35: n/a | F35: Tata Comm/Mastek/Happiest Minds add Indian context | G35: Balanced set on business economics & listing market; BB a clear premium | H35: Medium-High | I35: Yahoo/BSE/company - Aug-2026 (approx; refresh)
A36: FY27E EPS (relative base) | B36: =Forecast!D49 | C36: FY26 EPS ~Rs12.78 | D36: Consol PAT / 18.0cr shares (incl tax normalisation) | E36: n/a | F36: Drives target-price application | G36: Most sensitive to organic growth, margin & tax assumptions | H36: Medium | I36: Model Forecast/Relative
A37: Target P/E multiple | B37: Bear 18x / Base 25x / Bull 32x on FY27E EPS | C37: Peer median ~17-18x; BB trades ~65-70x | D37: Premium to peers for growth/DC exposure | E37: n/a | F37: WESCO 22x; Redington 16x; HCLT 19x | G37: A GROWTH PREMIUM to peers but a large DISCOUNT to BBs current ~65-70x (partial mean-reversion) | H37: Medium | I37: Peer multiples - 2026
A38: EV/EBITDA (cross-check) | B38: 15x FY27E EBITDA | C38: BB ~25-27x EV/EBITDA currently | D38: Third method; net debt Rs287cr | E38: n/a | F38: WESCO ~13x; Kyndryl ~5.5x | G38: Sanity check on P/E method; de-emphasised (20% weight) | H38: Medium | I38: Relative/Summary sheets
A39: F. EV/EBITDA CROSS-CHECK, BLEND & RECOMMENDATION
A40: Assumption | B40: Model value | C40: Historical trend | D40: Research & industry evidence | E40: Management commentary | F40: Govt policy / competitive benchmark | G40: Why reasonable & valuation impact | H40: Conf. | I40: Source - Date
...
